Workbook

Sheet Money Model
A1: The Launchpad — Money Model
A2: Backward math from revenue goal to email volume to infrastructure cost.
A3: Edit BLUE cells. Black cells are formulas — don't touch. Yellow cells are diagnostic-only (don't drive math).
A5: BENCHMARKS | B5: Close rate | C5: 0.2 | D5: Qual rate | E5: 0.8 | F5: Show rate | G5: 0.6 | H5: LTA | I5: 0.3 | J5: Reply rate | K5: 0.02 | L5: Pos reply rate | M5: 0.15
A7: TIME PERIOD
A8: Goal time period (days) | B8: 90 | C8: Months in period | D8: =B8/30 -> 3
A10: FUNNEL MATH BY ICP
A11: Metric | B11: SMB | C11: Mid-Market | D11: Enterprise | E11: ALL ICPs (Sum) | F11: Notes | G11: Warnings
A12: INPUTS — edit blue cells (math drivers)
A13: Revenue goal (over time period) | B13: 50000 | F13: Pick your specific dollar target for the goal time period.
A14: ACV — Annual contract value | B14: 10000 | F14: Average dollar value of a closed deal.
A15: Close rate (qualified call → deal) | B15: 0.25 | F15: What % of qualified calls become deals. Industry typical: 15-30%. | G15: =IF(OR(AND(B15>0,B15<$C$5),AND(C15>0,C15<$C$5),AND(D15>0,D15<$C$5)),"⚠ Below benchmark — see SOP 13","")
A16: Qualification rate (held call → qualified) | B16: 0.8 | F16: What % of held calls are qualified. Below 80% means targeting is off. | G16: =IF(OR(AND(B16>0,B16<$E$5),AND(C16>0,C16<$E$5),AND(D16>0,D16<$E$5)),"⚠ Below benchmark — see SOP 13","")
A17: Show rate (booked → held) | B17: 0.7 | F17: What % of booked calls actually happen. Cold email show rate is usually lower than inbound. | G17: =IF(OR(AND(B17>0,B17<$G$5),AND(C17>0,C17<$G$5),AND(D17>0,D17<$G$5)),"⚠ Below benchmark — see SOP 13","")
A18: LTA — Lead-to-Appointment (positive reply → booked) | B18: 0.3 | F18: What % of positive replies convert to a booked call. Below 30% means reply handling is broken. | G18: =IF(OR(AND(B18>0,B18<$I$5),AND(C18>0,C18<$I$5),AND(D18>0,D18<$I$5)),"⚠ Below benchmark — see SOP 13","")
A19: Leads contacted per positive reply | B19: 75 | F19: How many leads contacted, on average, to get one positive reply. Workshop benchmark: 50-100. Lower = better. (No warning — this metric varies by niche.)
A20: Email sequence length (# of emails per lead) | B20: 3 | F20: On average, a lead receives 1-2 emails (some convert early, some bounce, some unsubscribe, many don't reply at all).
A22: DIAGNOSTIC-ONLY — tracked but doesn't drive math (yellow cells)
A23: Reply rate (overall) | B23: 0.02 | C23: 0.02 | D23: 0.02 | F23: What % of contacted leads reply at all. Diagnostic only — used to spot problems, not in funnel math. Benchmark: 2%+. | G23: =IF(OR(B23<$K$5,C23<$K$5,D23<$K$5),"⚠ Reply rate below benchmark","")
A24: Positive reply rate (of replies) | B24: 0.15 | C24: 0.15 | D24: 0.15 | F24: What % of replies are positive. Diagnostic only. Benchmark: 15 | G24: =IF(OR(B24<$M$5,C24<$M$5,D24<$M$5),"⚠ Positive reply rate below benchmark","")
A26: FUNNEL OUTPUTS — auto-calculated (7 stages)
A27: Deals needed | B27: =IF(OR(B13=0,B14=0),0,ROUNDUP(B13/B14,0)) -> 5 | C27: =IF(OR(C13=0,C14=0),0,ROUNDUP(C13/C14,0)) -> 0 | D27: =IF(OR(D13=0,D14=0),0,ROUNDUP(D13/D14,0)) -> 0 | E27: =B27+C27+D27 -> 5 | F27: Revenue goal ÷ ACV
A28: Qualified calls needed | B28: =IF(OR(B27=0,B15=0),0,ROUNDUP(B27/B15,0)) -> 20 | C28: =IF(OR(C27=0,C15=0),0,ROUNDUP(C27/C15,0)) -> 0 | D28: =IF(OR(D27=0,D15=0),0,ROUNDUP(D27/D15,0)) -> 0 | E28: =B28+C28+D28 -> 20 | F28: Deals ÷ close rate
A29: Held calls needed | B29: =IF(OR(B28=0,B16=0),0,ROUNDUP(B28/B16,0)) -> 25 | C29: =IF(OR(C28=0,C16=0),0,ROUNDUP(C28/C16,0)) -> 0 | D29: =IF(OR(D28=0,D16=0),0,ROUNDUP(D28/D16,0)) -> 0 | E29: =B29+C29+D29 -> 25 | F29: Qualified calls ÷ qualification rate
A30: Booked calls needed | B30: =IF(OR(B29=0,B17=0),0,ROUNDUP(B29/B17,0)) -> 36 | C30: =IF(OR(C29=0,C17=0),0,ROUNDUP(C29/C17,0)) -> 0 | D30: =IF(OR(D29=0,D17=0),0,ROUNDUP(D29/D17,0)) -> 0 | E30: =B30+C30+D30 -> 36 | F30: Held calls ÷ show rate
A31: Positive replies needed | B31: =IF(OR(B30=0,B18=0),0,ROUNDUP(B30/B18,0)) -> 120 | C31: =IF(OR(C30=0,C18=0),0,ROUNDUP(C30/C18,0)) -> 0 | D31: =IF(OR(D30=0,D18=0),0,ROUNDUP(D30/D18,0)) -> 0 | E31: =B31+C31+D31 -> 120 | F31: Booked calls ÷ LTA ratio
A32: Leads to contact | B32: =IF(B31=0,0,ROUNDUP(B31*B19,0)) -> 9000 | C32: =IF(C31=0,0,ROUNDUP(C31*C19,0)) -> 0 | D32: =IF(D31=0,0,ROUNDUP(D31*D19,0)) -> 0 | E32: =B32+C32+D32 -> 9000 | F32: Positive replies × leads-per-positive ratio
A33: Total emails to send (over time period) | B33: =IF(B32=0,0,ROUNDUP(B32*B20*0.85,0)) -> 22950 | C33: =IF(C32=0,0,ROUNDUP(C32*C20*0.85,0)) -> 0 | D33: =IF(D32=0,0,ROUNDUP(D32*D20*0.85,0)) -> 0 | E33: =B33+C33+D33 -> 22950 | F33: Leads × sequence × ~0.85 (some leads only get email 1, some convert early)
A34: Monthly emails to send | B34: =IF(B33=0,0,ROUNDUP(B33/$D$8,0)) -> 7650 | C34: =IF(C33=0,0,ROUNDUP(C33/$D$8,0)) -> 0 | D34: =IF(D33=0,0,ROUNDUP(D33/$D$8,0)) -> 0 | E34: =B34+C34+D34 -> 7650 | F34: Total emails ÷ months in period — feeds Infra Calculator
A36: INFRA COST + ROI — pulls from Infra Calculator tab
A37: Monthly infra cost (cheap domains) | B37: =ROUND((ROUNDUP((B34/'Infra Calculator'!$C$24)*'Infra Calculator'!$C$10/'Infra Calculator'!$C$26,0)*'Infra Calculator'!$C$27+ROUNDUP(ROUNDUP((B34/'Infra Calculator'!$C$24)*'Infra Calculator'!$C$10/'Infra Calculator'!$C$26,0)/'Infra Calculator'!$C$25,0)*'Infra Calculator'!$C$34/3)+(ROUNDUP((B34/'Infra Calculator'!$C$24)*'Infra Calculator'!$C$11/'Infra Calculator'!$C$29,0)*'Infra Calculator'!$C$30+ROUNDUP(ROUNDUP((B34/'Infra Calculator'!$C$24)*'Infra Calculator'!$C$11/'Infra Calculator'!$C$29,0)/'Infra Calculator'!$C$28,0)*'Infra Calculator'!$C$34/3)+(ROUNDUP((B34/'Infra Calculator'!$C$24)*'Infra Calculator'!$C$12/'Infra Calculator'!$C$32,0)*'Infra Calculator'!$C$33+ROUNDUP(ROUNDUP((B34/'Infra Calculator'!$C$24)*'Infra Calculator'!$C$12/'Infra Calculator'!$C$32,0)/'Infra Calculator'!$C$31,0)*'Infra Calculator'!$C$34/3)+(B34/30000*300),2) -> 169.83 | C37: =ROUND((ROUNDUP((C34/'Infra Calculator'!$C$24)*'Infra Calculator'!$C$10/'Infra Calculator'!$C$26,0)*'Infra Calculator'!$C$27+ROUNDUP(ROUNDUP((C34/'Infra Calculator'!$C$24)*'Infra Calculator'!$C$10/'Infra Calculator'!$C$26,0)/'Infra Calculator'!$C$25,0)*'Infra Calculator'!$C$34/3)+(ROUNDUP((C34/'Infra Calculator'!$C$24)*'Infra Calculator'!$C$11/'Infra Calculator'!$C$29,0)*'Infra Calculator'!$C$30+ROUNDUP(ROUNDUP((C34/'Infra Calculator'!$C$24)*'Infra Calculator'!$C$11/'Infra Calculator'!$C$29,0)/'Infra Calculator'!$C$28,0)*'Infra Calculator'!$C$34/3)+(ROUNDUP((C34/'Infra Calculator'!$C$24)*'Infra Calculator'!$C$12/'Infra Calculator'!$C$32,0)*'Infra Calculator'!$C$33+ROUNDUP(ROUNDUP((C34/'Infra Calculator'!$C$24)*'Infra Calculator'!$C$12/'Infra Calculator'!$C$32,0)/'Infra Calculator'!$C$31,0)*'Infra Calculator'!$C$34/3)+(C34/30000*300),2) -> 0 | D37: =ROUND((ROUNDUP((D34/'Infra Calculator'!$C$24)*'Infra Calculator'!$C$10/'Infra Calculator'!$C$26,0)*'Infra Calculator'!$C$27+ROUNDUP(ROUNDUP((D34/'Infra Calculator'!$C$24)*'Infra Calculator'!$C$10/'Infra Calculator'!$C$26,0)/'Infra Calculator'!$C$25,0)*'Infra Calculator'!$C$34/3)+(ROUNDUP((D34/'Infra Calculator'!$C$24)*'Infra Calculator'!$C$11/'Infra Calculator'!$C$29,0)*'Infra Calculator'!$C$30+ROUNDUP(ROUNDUP((D34/'Infra Calculator'!$C$24)*'Infra Calculator'!$C$11/'Infra Calculator'!$C$29,0)/'Infra Calculator'!$C$28,0)*'Infra Calculator'!$C$34/3)+(ROUNDUP((D34/'Infra Calculator'!$C$24)*'Infra Calculator'!$C$12/'Infra Calculator'!$C$32,0)*'Infra Calculator'!$C$33+ROUNDUP(ROUNDUP((D34/'Infra Calculator'!$C$24)*'Infra Calculator'!$C$12/'Infra Calculator'!$C$32,0)/'Infra Calculator'!$C$31,0)*'Infra Calculator'!$C$34/3)+(D34/30000*300),2) -> 0 | E37: =B37+C37+D37+'Infra Calculator'!$C$63+'Infra Calculator'!$C$64 -> 712.83 | F37: Per-ICP VARIABLE cost: sending infra (Google+M365+Azure) + data, cheap-domain rates. ALL-ICPs column adds fixed software (sequencer+Clay) once.
A38: Monthly infra cost (premium domains) | B38: =ROUND((ROUNDUP((B34/'Infra Calculator'!$C$24)*'Infra Calculator'!$C$10/'Infra Calculator'!$C$26,0)*'Infra Calculator'!$C$27+ROUNDUP(ROUNDUP((B34/'Infra Calculator'!$C$24)*'Infra Calculator'!$C$10/'Infra Calculator'!$C$26,0)/'Infra Calculator'!$C$25,0)*'Infra Calculator'!$C$35/3)+(ROUNDUP((B34/'Infra Calculator'!$C$24)*'Infra Calculator'!$C$11/'Infra Calculator'!$C$29,0)*'Infra Calculator'!$C$30+ROUNDUP(ROUNDUP((B34/'Infra Calculator'!$C$24)*'Infra Calculator'!$C$11/'Infra Calculator'!$C$29,0)/'Infra Calculator'!$C$28,0)*'Infra Calculator'!$C$35/3)+(ROUNDUP((B34/'Infra Calculator'!$C$24)*'Infra Calculator'!$C$12/'Infra Calculator'!$C$32,0)*'Infra Calculator'!$C$33+ROUNDUP(ROUNDUP((B34/'Infra Calculator'!$C$24)*'Infra Calculator'!$C$12/'Infra Calculator'!$C$32,0)/'Infra Calculator'!$C$31,0)*'Infra Calculator'!$C$35/3)+(B34/30000*300),2) -> 187.17 | C38: =ROUND((ROUNDUP((C34/'Infra Calculator'!$C$24)*'Infra Calculator'!$C$10/'Infra Calculator'!$C$26,0)*'Infra Calculator'!$C$27+ROUNDUP(ROUNDUP((C34/'Infra Calculator'!$C$24)*'Infra Calculator'!$C$10/'Infra Calculator'!$C$26,0)/'Infra Calculator'!$C$25,0)*'Infra Calculator'!$C$35/3)+(ROUNDUP((C34/'Infra Calculator'!$C$24)*'Infra Calculator'!$C$11/'Infra Calculator'!$C$29,0)*'Infra Calculator'!$C$30+ROUNDUP(ROUNDUP((C34/'Infra Calculator'!$C$24)*'Infra Calculator'!$C$11/'Infra Calculator'!$C$29,0)/'Infra Calculator'!$C$28,0)*'Infra Calculator'!$C$35/3)+(ROUNDUP((C34/'Infra Calculator'!$C$24)*'Infra Calculator'!$C$12/'Infra Calculator'!$C$32,0)*'Infra Calculator'!$C$33+ROUNDUP(ROUNDUP((C34/'Infra Calculator'!$C$24)*'Infra Calculator'!$C$12/'Infra Calculator'!$C$32,0)/'Infra Calculator'!$C$31,0)*'Infra Calculator'!$C$35/3)+(C34/30000*300),2) -> 0 | D38: =ROUND((ROUNDUP((D34/'Infra Calculator'!$C$24)*'Infra Calculator'!$C$10/'Infra Calculator'!$C$26,0)*'Infra Calculator'!$C$27+ROUNDUP(ROUNDUP((D34/'Infra Calculator'!$C$24)*'Infra Calculator'!$C$10/'Infra Calculator'!$C$26,0)/'Infra Calculator'!$C$25,0)*'Infra Calculator'!$C$35/3)+(ROUNDUP((D34/'Infra Calculator'!$C$24)*'Infra Calculator'!$C$11/'Infra Calculator'!$C$29,0)*'Infra Calculator'!$C$30+ROUNDUP(ROUNDUP((D34/'Infra Calculator'!$C$24)*'Infra Calculator'!$C$11/'Infra Calculator'!$C$29,0)/'Infra Calculator'!$C$28,0)*'Infra Calculator'!$C$35/3)+(ROUNDUP((D34/'Infra Calculator'!$C$24)*'Infra Calculator'!$C$12/'Infra Calculator'!$C$32,0)*'Infra Calculator'!$C$33+ROUNDUP(ROUNDUP((D34/'Infra Calculator'!$C$24)*'Infra Calculator'!$C$12/'Infra Calculator'!$C$32,0)/'Infra Calculator'!$C$31,0)*'Infra Calculator'!$C$35/3)+(D34/30000*300),2) -> 0 | E38: =B38+C38+D38+'Infra Calculator'!$C$63+'Infra Calculator'!$C$64 -> 730.17 | F38: Per-ICP VARIABLE cost at premium-domain rates. ALL-ICPs column adds fixed software (sequencer+Clay) once.
A39: Monthly revenue (goal ÷ months) | B39: =B13/$D$8 -> 16666.667 | C39: =C13/$D$8 -> 0 | D39: =D13/$D$8 -> 0 | E39: =B39+C39+D39 -> 16666.667 | F39: Revenue goal converted to monthly basis.
A40: Monthly ROI (revenue ÷ infra, cheap domains) | B40: =IF(B37=0,0,B39/B37) -> 98.137353 | C40: =IF(C37=0,0,C39/C37) -> 0 | D40: =IF(D37=0,0,D39/D37) -> 0 | E40: =IF(E37=0,0,E39/E37) -> 23.380984 | F40: Dollars of revenue per dollar of infra spend, monthly.
A41: Return on Marketing Spend per 10K emails ($) | B41: =IF(B34=0,0,B39/B34*10000) -> 21786.492 | C41: =IF(C34=0,0,C39/C34*10000) -> 0 | D41: =IF(D34=0,0,D39/D34*10000) -> 0 | F41: Revenue earned per 10K emails sent — useful for comparing ICPs head-to-head.
A44: HOW TO USE THIS MODEL
A45: 1. Set your goal time period (default 90 days).
A46: 2. For each ICP column, enter your revenue goal and ACV. - if only 1 ICP, delete blue metrics from other ICP columns
A47: 3. Enter your conversion rates and leads-per-positive ratio. If you don't have data yet, the defaults are workshop benchmarks.
A48: 4. Reply rate and positive reply rate are diagnostic-only (yellow cells) — track them but they don't drive the funnel math.
...

Sheet Infra Calculator
A1: The Launchpad — Infrastructure Cost Calculator
A2: Edit BLUE cells. YELLOW cells are the Google / Microsoft 365 / Azure split — change them to test infra mixes. Black cells are formulas — don’t touch.
A3: DISCLAIMER: Provider pricing changes. This is June 2026 pricing — verify current rates before signing up.
B5: STEP 1 — ENTER YOUR MONTHLY SEND VOLUME
B6: Monthly send volume (total across all ICPs/campaigns) | C6: 22950 | D6: ← Pull from Money Model, or enter manually
B7: Daily send volume | C7: =C6/$C$24 -> 1043.1818
B9: STEP 2 — SET THE GOOGLE / MICROSOFT 365 / AZURE SPLIT
B10: 🟡 Google % of total volume | C10: 1
B11: 🟡 Microsoft 365 % of total volume | C11: 0
B12: 🟡 Azure % of total volume | C12: 0
B13: Split validity check | C13: =IF(ROUND(C10+C11+C12,4)=1,"✓ Splits sum to 100%","⚠ Must sum to 100% — now "&TEXT((C10+C11+C12)*100,"0")&"%") -> ✓ Splits sum to 100%
B15: Common split scenarios (copy values into the yellow cells above to test)
B16: Scenario | C16: Google % | D16: M365 % | E16: Azure % | F16: When to use
B17: Google-only — start here | C17: 100% | D17: 0% | E17: 0% | F17: First 90 days; send to non-Outlook ESP leads
B18: Google + Azure scale hedge | C18: 70% | D18: 0% | E18: 30% | F18: Add cheap volume once the system is proven
B19: Outlook / SEG-heavy TAM (aged M365) | C19: 30% | D19: 50% | E19: 20% | F19: Enterprise/regulated; requires 3-month aged M365
B20: Volume-cost optimized | C20: 20% | D20: 0% | E20: 80% | F20: Cheapest at scale; watch Azure pooled-reputation risk
B21: Microsoft-only (aged) | C21: 0% | D21: 100% | E21: 0% | F21: Pure Outlook/SEG TAM with aged M365 infra
B23: STEP 3 — UNIT COSTS (editable)
B24: Sending days per month | C24: 22
B25: Google: inboxes per domain | C25: 3
B26: Google: emails per inbox per day | C26: 15
B27: Google: cost per inbox / month | C27: 3.5
B28: Microsoft 365: inboxes per domain | C28: 3
B29: Microsoft 365: emails per inbox per day | C29: 10
B30: Microsoft 365: cost per inbox / month | C30: 3.5
B31: Azure: inboxes per domain | C31: 50
B32: Azure: emails per inbox per day | C32: 2
B33: Azure: cost per inbox / month | C33: 0.6
B34: Cheap domain cost | C34: 3.5
B35: Premium domain cost | C35: 10
B36: (Business sending reuses domains over a quarter → domain cost ÷3 monthly. Personal-email sending refreshes every 30 days — see the Personal Email tab.)
B38: GOOGLE INFRASTRUCTURE — auto-calculated from your split
B39: Daily volume on Google | C39: =C7*$C$10 -> 1043.1818
B40: Inboxes needed | C40: =ROUNDUP(C39/$C$26,0) -> 70
B41: Domains needed | C41: =ROUNDUP(C40/$C$25,0) -> 24
B42: Inbox cost / month | C42: =C40*$C$27 -> 245
B43: Domain cost / month (cheap) | C43: =C41*$C$34/3 -> 28
B44: Domain cost / month (premium) | C44: =C41*$C$35/3 -> 80
B46: MICROSOFT 365 INFRASTRUCTURE — auto-calculated from your split
...

Sheet Infra Calc — Personal Email
A1: The Launchpad — Infrastructure Cost Calculator (PERSONAL-EMAIL SENDING)
A2: Edit BLUE cells. YELLOW cells are the Google/Azure split + the cycling multiplier. Black cells are formulas — don't touch.
A3: DISCLAIMER: Provider pricing changes. This is June 2026 pricing — verify current rates before signing up.
B5: WHY PERSONAL-EMAIL INFRA IS DIFFERENT
B6: Sending to personal inboxes (@gmail, @outlook) burns infrastructure fast, so you can never sit still. You always run ONE live batch while warming its replacement — so you hold TWO full batches (inboxes + domains) at all times. The cycle: buy Batch 1 → warm 14 days → it goes live on the 15th. Same day you buy Batch 2 and warm it. When Batch 2 is warm, you kill Batch 1, Batch 2 sends, and you buy Batch 3. The snake eats its tail forever. Net effect vs business sending: (1) domains are NOT reused — you pay full registration every cycle (no quarterly ÷3 amortization), and (2) inboxes + domains are both multiplied by the cycling factor. Software & data are NOT cycled (they're subscriptions, billed 1×).
B8: STEP 1 — ENTER YOUR MONTHLY SEND VOLUME
B9: Monthly send volume (total across all ICPs/campaigns) | C9: 30000 | D9: ← Pull from Money Model, or enter manually
B10: Daily send volume | C10: =C9/$C$18 -> 1000 | D10: Auto-calculated from monthly volume ÷ sending days/month
B12: STEP 2 — SET THE GOOGLE / AZURE SPLIT
B13: 🟡 Google % of total volume | C13: 1 | D13: Personal sends often skew Google (recipients are mostly @gmail) — but keep the hedge unless you have data.
B14: 🟡 Azure % of total volume
B15: Split validity check | C15: =IF(C13+C14=1,"✓ Splits sum to 100%","⚠ Splits must sum to 100% — currently "&TEXT((C13+C14)*100,"0")&"%") -> ✓ Splits sum to 100%
B17: STEP 3 — UNIT COSTS + CYCLING (editable)
B18: Sending days per month | C18: 30 | D18: Calendar-aligned. Sibling business tab uses the same value for apples-to-apples.
B19: Google: inboxes per domain | C19: 3 | D19: Google's safe limit is max 3 per domain
B20: Google: emails per inbox per day | C20: 15 | D20: Warm-up baseline
B21: Google: cost per inbox / month | C21: 3.5 | D21: Can range $3–$3.5 at volume
B22: Azure: inboxes per domain | C22: 50 | D22: Azure higher limit — we recommend keeping at 50
B23: Azure: emails per inbox per day | C23: 2
B24: Azure: cost per inbox / month | C24: 0.6 | D24: Can range $0.4–$0.6 at volume
B25: Cheap domain cost (per registration) | C25: 3.5 | D25: Full price you pay each cycle — no quarterly reuse on personal sending
B26: Premium domain cost (per registration) | C26: 10 | D26: Once system is proven
B27: ⭐ Cycling multiplier (batches live at once) | C27: 2 | D27: 2.0 = buy on the 1st & 15th (clean 2×). Use 2.17 for the strict 14-day clock (never a single-batch day → ~26 buys/yr).
B29: GOOGLE INFRASTRUCTURE — per batch (one batch carries the full daily volume)
B30: Daily volume on Google | C30: =C10*$C$13 -> 1000
B31: Inboxes needed (per batch) | C31: =ROUNDUP(C30/$C$20,0) -> 67
B32: Domains needed (per batch) | C32: =ROUNDUP(C31/$C$19,0) -> 23
B33: Inbox cost / month (per batch) | C33: =C31*$C$21 -> 234.5
B34: Domain cost (per batch, cheap) | C34: =C32*$C$25 -> 80.5 | D34: Full registration — NOT divided by a quarter, because the domain is discarded after one cycle.
B35: Domain cost (per batch, premium) | C35: =C32*$C$26 -> 230
B37: AZURE INFRASTRUCTURE — per batch
B38: Daily volume on Azure | C38: =C10*$C$14 -> 0
B39: Inboxes needed (per batch) | C39: =ROUNDUP(C38/$C$23,0) -> 0
B40: Domains needed (per batch) | C40: =ROUNDUP(C39/$C$22,0) -> 0
B41: Inbox cost / month (per batch) | C41: =C39*$C$24 -> 0
B42: Domain cost (per batch, cheap) | C42: =C40*$C$25 -> 0
B43: Domain cost (per batch, premium) | C43: =C40*$C$26 -> 0
B45: PERSONAL-EMAIL CYCLING — you hold 2 batches at all times
B46: Per-batch inbox cost (Google + Azure) | C46: =C33+C41 -> 234.5
B47: Per-batch domain cost (cheap) | C47: =C34+C42 -> 80.5
...
